Workbook

Sheet Start Here
A1: CLIMATE-RESILIENT TREE REMOVAL AND REPLACEMENT — START HERE
A2: A planning and record-keeping tool for replacing high-maintenance plantings with climate-adapted species in the southern Willamette Valley, Oregon. It suits arborists, landscape managers, public agencies and property owners. Use the workflows below. Each step names the tab to open.
A4: SETTINGS — change these here only
A5: Setting | B5: Value | C5: Used by
A6: Labor rate ($/hour) | B6: 150 | C6: Conversion Economics, Establishment Water. Placeholder: enter your own rate.
A7: Planning horizon (years) | B7: 15 | C7: Conversion Economics. Use the number of years you expect to manage the site.
A8: Dry season length (days) | B8: 122 | C8: Establishment Water, Watering Plan. June 15 to October 15.
A9: Tier B cap (share of plants per install) | B9: 0.1 | C9: Planting plans, Program Review.
A10: Minimum plants before diversity flags count | B10: 30 | C10: Program Review. Below this number the flags show 'too few plants'.
A12: TABS — WHAT EACH ONE IS FOR
A13: Tab | B13: Group | C13: Use it to
A14: Field Card | B14: Field | C14: Record a site assessment. Print it. Carry it.
A15: Conversion Crosswalk | B15: Plan | C15: Find what replaces a legacy plant, and why.
A16: Ash EAB | B16: Plan | C16: EAB status, treatment costs, decision rules, phased replacement, quarantine and safety.
A17: Palette | B17: Plan | C17: Choose species by soil group, size, tier and water class.
A18: Hedgerow Design | B18: Plan | C18: Design a mixed hedgerow and count the plants.
A19: Establishment Water | B19: Plan | C19: Calculate the 3-year watering plan and its cost for one site.
A20: Watering Plan | B20: Plan | C20: Print the watering schedule for whoever waters. It fills from Establishment Water.
A21: Conversion Economics | B21: Plan | C21: Compare the cost of the old planting with the conversion.
A22: Install Log | B22: Records | C22: Record every install. Score condition at each visit.
A23: Ash Register | B23: Records | C23: Record every ash tree. Recommendation, costs and next treatment fill in.
A24: Program Review | B24: Records | C24: Check survival and diversity once a year. Updates by itself.
A25: Reference | B25: Reference | C25: Tier rules, soil groups, water classes, palette summary and sources.
A27: W1. ASSESS A SITE
A28: Step 1 | B28: Open a blank Field Card. It takes about 4 minutes.
A29: Step 2 | B29: Name the legacy plant and the scope (length, width or stem count).
A30: Step 3 | B30: Call the soil group. If you are not sure, dig 18 in and fill the hole with water. If it has not drained in 1 hour, call it Group 1.
A31: Step 4 | B31: Mark the class: Remove soon (failing or hazardous) or Optional (healthy but costly to keep).
A32: Step 5 | B32: Take photos. File the card.
B33: RULE: Recommend a replacement only where the plant needs it. Otherwise note the condition and move on.
A35: W2. SET PRIORITIES — once a month
A36: Step 1 | B36: Act on Remove soon cards first. These plants are failing or hazardous.
A37: Step 2 | B37: Hold Optional cards. They pay back best where the site will be managed for 10 years or more.
A38: Step 3 | B38: Keep all other cards on file as observed conditions. Check them at the next visit.
A40: W3. PLAN A REPLACEMENT
A41: Step 1 | B41: Conversion Crosswalk: find the legacy plant. Read the soil notes and the considerations. For ash, go to workflow W8 instead.
A42: Step 2 | B42: Palette: filter the site's soil group column to 'Yes'. Check Tier, Max Ht, Under Wires, Water Class and Review By.
A43: Step 3 | B43: If the hedge site is 8 ft wide or more, offer a hedgerow. Use Hedgerow Design for the mix and the plant count.
A44: Step 4 | B44: Establishment Water: enter the soil group and each plant line. Note the 3-year watering cost if the watering is hired out.
A45: Step 5 | B45: Conversion Economics: enter the site numbers in the matching column. Use the cost curve for Optional replacements. Use the cost-of-waiting line for Remove soon replacements.
...

Sheet Field Card
A1: CONVERSION FIELD CARD
A2: Fill on site. Create an Install Log or Ash Register row after the visit.
A3: Owner | C3: Date
A4: Address | C4: Assessed by
A5: THE PLANT
A6: Legacy plant | B6: laurel / boxwood / arborvitae / photinia / birch / pear / plum / ash | C6: Scope | D6: length and width (ft), or stem count
A7: Class | B7: REMOVE SOON / OPTIONAL / PLAN SUCCESSION | C7: Condition | D7: good / fair / poor / failing
A8: THE SITE
A9: Soil group | B9: 1 / 2 / 3 (see below) | C9: Aspect | D9: N NE E SE S SW W NW
A10: Water access | B10: irrigated? / hose bib distance | C10: Overhead wires | D10: Y / N
A11: Rooting volume | B11: open / restricted / severe | C11: Deer pressure | D11: none / moderate / heavy
A12: ASH ONLY — one card per ash tree
A13: DBH (in) | C13: Canopy dieback % | D13: estimate, top down
A14: EAB signs | B14: D-holes / woodpecker / splits / sprouts / none | C14: Near target | D14: house / road / play area / none
A15: Tree value | B15: high / medium / low | C15: Site type | D15: upland / wet / riparian
A16: THE CALL
A17: Recommended replacement | B17: from the quick reference below; ash: Ash Register decides
A18: Owner interest | B18: high / some / none | C18: Photos taken | D18: Y / N
A19: Follow-up action | B19: plan replacement / revisit / no action / add to phased plan
A20: Notes
A22: QUICK REFERENCE
A23: Legacy plant | B23: Primary replacement | C23: Class | D23: Note
A24: English laurel | B24: Pacific wax myrtle | C24: Optional | D24: Maintenance cost; city-listed invasive
A25: Boxwood | B25: Osmanthus delavayi | C25: Optional | D25: Best payback; blight risk
A26: Arborvitae | B26: Incense cedar | C26: Remove soon | D26: Not western redcedar
A27: Photinia | B27: Osmanthus x burkwoodii | C27: Remove soon | D27: Ends a recurring failure
A28: Birch | B28: Parrotia persica | C28: Remove soon | D28: No white-bark equivalent
A29: Bradford pear | B29: Parrotia persica | C29: Remove soon | D29: Plan removal before failure
A30: Flowering plum | B30: Cotinus 'Royal Purple' | C30: Remove soon | D30: Keeps purple foliage
A31: Ash (EAB) | B31: Treat, plant first, or replace | C31: Plan succession | D31: Use the Ash EAB tab
A32: Any hedge 8+ ft wide | B32: Mixed hedgerow | C32: — | D32: See Hedgerow Design tab
A34: SOIL GROUP — FIELD CALL
A35: Group 1 | B35: Valley bottom clay. Sticky when wet, cracks when dry. Mottled or grey-green at depth. Standing water in winter.
A36: Group 2 | B36: Alluvial silt loam. Dark, crumbly, drains freely, no mottling. Floodplain and low terrace.
A37: Group 3 | B37: Footslope or upland red clay. Reddish, on a slope, sheds water, moderately deep (Nekia, Bellpine, Dixonville) to very deep (Jory) over bedrock. Dry in summer.
A38: If unsure | B38: Dig 18 in. Fill with water. Not drained in 1 hour = Group 1, whatever the soil survey says.
A40: Remove soon = failing or hazardous: plan around timing and risk. Optional = healthy but costly to keep: compare the 15-year cost. Plan succession = healthy ash before EAB arrives: treat, or plant a successor first. Suspected EAB in Lane County: report it; do not move the wood.

Sheet Conversion Crosswalk
A1: Legacy Plant | B1: Typical Form | C1: Class | D1: Why It Costs / Fails | E1: Primary Replacement | F1: Alternates | G1: Soil Group Notes | H1: Maintenance Delta | I1: Considerations
A2: Prunus laurocerasus | B2: English laurel hedge | C2: Optional | D2: Grows 2-3 ft a year, so it is sheared 2-3 times a year for as long as it stands. Shot hole fungus in wet springs. The City of Eugene lists it as invasive: birds carry the seed into forest understory. | E2: Morella californica (Pacific wax myrtle) | F2: Osmanthus x burkwoodii (formal); Calocedrus decurrens (tall screen); Frangula californica 'Eve Case' (medium) | G2: Wax myrtle works on all three groups. Osmanthus and Frangula want drainage - berm on Group 1. | H2: 2-3 shearings/yr down to 1 | I2: It is healthy, so the reason to replace it is cost and spread. Over 15 years, shearing costs more than the conversion. The City of Eugene lists it as invasive: birds carry its seed into nearby woods.
A3: Buxus sempervirens | B3: Low formal hedge, balls | C3: Optional | D3: Sheared 2-3x/yr to hold form. Boxwood blight has been found in Oregon nurseries and landscapes since 2011. Infected plants must be removed and destroyed. Leafminer and psyllid add spray cycles. | E3: Osmanthus delavayi | F3: Berberis aquifolium 'Compacta' (informal low mass); dwarf Arctostaphylos or prostrate rosemary on hot dry edges | G3: Osmanthus prefers drainage - Group 2 and 3 first. On Group 1, use Berberis aquifolium. | H3: 3 shearings/yr down to 1 | I3: The best payback of the hedge conversions, because shearing frequency drives the cost. Boxwood blight is the other risk: once it reaches a hedge, it can take the whole planting.
A4: Thuja occidentalis | B4: 'Emerald Green' privacy hedge | C4: Remove soon | D4: Shallow-rooted and increasingly drought-stressed in valley summers. Flagging, spider mites, Phytophthora, deer browse. Individual plants die and leave gaps that cannot be filled in kind. | E4: Calocedrus decurrens (incense cedar) | F4: Morella californica (shorter); Hesperocyparis arizonica on sharply drained sites only | G4: Incense cedar on Groups 2 and 3; wax myrtle on Group 1. Do NOT default to western redcedar - Thuja plicata is itself in drought decline across the valley. | H4: Shearing plus ongoing gap replacement, down to periodic thinning | I4: If plants are already dying one at a time, replacing the whole run once costs less than patching it every year.
A5: Photinia x fraseri | B5: Red tip hedge | C5: Remove soon | D5: Entomosporium leaf spot is near-inevitable in valley wet springs, and shearing makes it worse by forcing susceptible new growth. Fungicide cycles plus shearing means up to 4 visits/yr on a plant that keeps declining. | E5: Osmanthus x burkwoodii | F5: Morella californica; Arbutus unedo 'Compacta' (red stems, winter flowers and fruit) | G5: Osmanthus and Arbutus want drainage. Wax myrtle for Group 1. | H5: Up to 4 visits/yr down to 1, and spraying stops | I5: Leaf spot returns every wet spring. Replacing it ends a recurring failure rather than changing a healthy planting.
A6: Betula pendula / papyrifera | B6: Specimen or clump birch | C6: Remove soon | D6: Bronze birch borer plus chronic summer drought stress. Aphid honeydew on cars and patios. Once crown dieback starts in the valley it does not reverse. | E6: Parrotia persica | F6: Quercus imbricaria (if space); Arbutus unedo 'Marina' multi-stem (evergreen); Acer griseum (not in Palette; needs more water) | G6: Parrotia works Groups 1 and 2, caution on 3. Bur or swamp white oak for wet Group 1 with room. | H6: Removal risk falls; pruning roughly halves | I6: No drought-tolerant tree has the same white bark. Choose the replacement for bark, structure and fall color instead.
A7: Pyrus calleryana | B7: 'Bradford' street/yard tree | C7: Remove soon | D7: Included bark at codominant unions causes structural failure at roughly 15-25 years, usually in an ice or wind event. Fireblight. Invasive seedling spread from fertile cultivar crosses. | E7: Parrotia persica | F7: Maackia amurensis (under wires); Quercus imbricaria (larger sites); Arbutus unedo 'Marina' | G7: Parrotia and Maackia are fine on Groups 1 and 2. Shingle oak on Groups 1 and 2 where there is room. Arbutus needs drainage: Groups 2 and 3 only. Maackia for small rooting volume. | H7: Structural pruning cycle replaces failure response | I7: Replacement rarely pays for itself in maintenance savings. The reason is timing: the tree will fail, and a planned removal is cheaper and safer than an emergency one.
A8: Prunus cerasifera | B8: 'Thundercloud' flowering plum | C8: Remove soon | D8: Short-lived at 20-25 years. Aphids, brown rot, bacterial canker, borers. Fruit litter and root suckering. Most valley specimens are already past their useful life. | E8: Cotinus coggygria 'Royal Purple' | F8: Parrotia persica; Maackia amurensis; Cercis canadensis 'Forest Pansy' (not in Palette; needs more water) | G8: Cotinus wants drainage - Group 2 and 3. Parrotia for Group 1. | H8: Ends aphid/fruit callbacks; pruning drops sharply | I8: Smokebush keeps the purple foliage that made the plum the choice, and it handles drought. Matching the look is what makes the change stick.
A9: Fraxinus spp. | B9: Oregon, green and white ash | C9: Plan succession | D9: EAB is confirmed in five northern Willamette Valley counties, as close as Salem. It is not confirmed in Lane County as of August 2026. Untreated ash will die once EAB arrives. Treated ash needs injection every 2-3 years while EAB is present. Eugene does not allow ash planting on public land. | E9: Decide per tree in the Ash Register tab: treat, plant first, or replace. Replacements: Quercus bicolor (wet) / Quercus garryana (upland) | F9: Quercus macrocarpa; Malus fusca (wet sites, small spaces); Quercus imbricaria; Parrotia persica. Riparian sites: natives only (Malus fusca, Salix, Q. garryana). | G9: Swamp white oak is the strongest analog for the wet bottomland niche Oregon ash holds. Bur oak second. Garry oak on Group 3. Use Pacific crabapple between oaks to keep the oak share down. | H9: Treat: injection every 2-3 years. Replace: ends treatment and the risk of a dead tree. | I9: For one tree, treatment usually costs less than replacement over 15 years. Treat healthy, valuable trees before EAB arrives. For the rest, plant a successor now so there is shade when the ash comes out. Never let an untreated ash die near a house or road.
A11: READING THE CLASS COLUMN
A12: REMOVE SOON: the plant is failing, structurally unsound or under pest pressure. The cost will come anyway; the choice is when. Maintenance savings are not the reason. Hazard, timing and the cost of waiting are.
A13: OPTIONAL: the plant is healthy but costly to keep. The cost curve is the reason. It needs a long horizon: 10 or more years under the same management. Payback runs 5-10 years.
A14: Do Remove soon replacements first. Their results show how the palette performs before Optional work starts.
A16: HEDGEROW OPTION
A17: For laurel, arborvitae and photinia hedges on sites 8 ft wide or more, consider a mixed hedgerow. It replaces one species with 6-10 and ends shearing. See the Hedgerow Design tab.
A19: SOURCE NOTE
A20: Invasive status: City of Eugene Native and Non-Native Plant List (Ordinance 20351, Exhibit F) names English laurel, sweet cherry and black locust as invasive. English laurel is not confirmed on the state noxious weed list.
A22: PLAN SUCCESSION CLASS (ash in Lane County)
A23: PLAN SUCCESSION: the plant is healthy now but faces a known threat. Today this means ash before EAB reaches Lane County. It is not failing. Treat high-value trees and plant a successor for the rest. It becomes Remove soon when the threat arrives. See the Ash EAB tab.

Sheet Ash EAB
A1: ASH TREES AND EMERALD ASH BORER (EAB)
A2: Use this tab for every ash tree you manage. Decide per tree: treat, plant a successor first, or remove and replace. Record each tree in the Ash Register tab. The recommendation and costs fill in there.
A4: EAB STATUS — check every 3 months
A5: Confirmed counties | B5: Clackamas, Marion, Multnomah, Washington and Yamhill (ODA quarantine). Nearest confirmed sites to Eugene: Salem and Silverton (2026).
A6: Lane County | B6: Not confirmed as of August 2026 reports. Ash in Lane is in the Plan succession window: treatment works best now, before infestation.
A7: Status last checked | B7: 46301 | C7: Update this date each time you check. Sources: oregon-eab-geo.hub.arcgis.com and the ODA EAB page.
A8: Next check due | B8: =$B$7+90 -> 46391 | C8: Amber within 30 days, red when overdue.
A10: COSTS — placeholders, replace with local prices
A11: Injection cost ($ per inch DBH, per treatment) | B11: 12 | C11: Emamectin benzoate trunk injection. Published range about $7-16 per inch.
A12: Retreatment interval (years) | B12: 2 | C12: Labels allow 2-3 years. Use 2 to stay conservative.
A13: Planned removal ($ per inch DBH) | B13: 80 | C13: Placeholder. An 18 in tree = $1,440. Published range for 18 in: about $1,200-2,400.
A14: Emergency multiplier for dead ash | B14: 1.5 | C14: Dead ash is brittle. Lift or crane, more rigging, more risk.
A15: Replacement tree, installed, with 3-year establishment ($) | B15: 1350 | C15: Stock, install labor and 3-year establishment care. Matches Conversion Economics.
A16: DBH used in Conversion Economics (in) | B16: 18 | C16: Example tree for the Ash column on that tab.
A17: Planning horizon (years) | B17: ='Start Here'!$B$7 -> 15 | C17: From Start Here.
A19: REGISTER SUMMARY — updates from the Ash Register
A20: Ash trees recorded | B20: =COUNTA('Ash Register'!$D$3:$D$302) -> 0
A21: Recommendation: REMOVE NOW | B21: =COUNTIF('Ash Register'!$J$3:$J$302,"REMOVE NOW*") -> 0
A22: Recommendation: GRAY ZONE | B22: =COUNTIF('Ash Register'!$J$3:$J$302,"GRAY*") -> 0
A23: Recommendation: TREAT | B23: =COUNTIF('Ash Register'!$J$3:$J$302,"TREAT") -> 0
A24: Recommendation: PLANT FIRST, REMOVE LATER | B24: =COUNTIF('Ash Register'!$J$3:$J$302,"PLANT FIRST*") -> 0
A25: Recommendation: REMOVE AND REPLACE | B25: =COUNTIF('Ash Register'!$J$3:$J$302,"REMOVE AND*") -> 0
A26: Trees under treatment | B26: =COUNTIF('Ash Register'!$Q$3:$Q$302,"Treated") -> 0
A27: Treatments overdue | B27: =COUNTIFS('Ash Register'!$S$3:$S$302,"<"&TODAY()) -> 0
A28: Inches of DBH under treatment | B28: =SUMIF('Ash Register'!$Q$3:$Q$302,"Treated",'Ash Register'!$D$3:$D$302) -> 0
A29: Treatment cost per year, all treated trees | B29: =SUMIF('Ash Register'!$Q$3:$Q$302,"Treated",'Ash Register'!$D$3:$D$302)*'Ash EAB'!$B$11/'Ash EAB'!$B$12 -> 0
A31: DECISION RULES — the Ash Register applies these
A32: 1. | B32: More than 50% canopy dieback: REMOVE NOW. The damaged trunk cannot move insecticide. Dead ash turns brittle fast.
A33: 2. | B33: 30-50% dieback: GRAY ZONE. Assess the structure. Treat only a high-value tree with sound structure. Otherwise remove.
A34: 3. | B34: Less than 30% dieback and high value: TREAT. Inject every 2-3 years for as long as EAB is present. Start before EAB arrives.
A35: 4. | B35: Less than 30% dieback, EAB signs present, not high value: REMOVE AND REPLACE on a planned schedule.
A36: 5. | B36: Less than 30% dieback, no signs, not high value: PLANT FIRST, REMOVE LATER (phased replacement, below).
A37: 6. | B37: Near a target (house, road, play area): never let an untreated ash die in place.
A39: CONVERSION CLASS — PLAN SUCCESSION
A40: Ash in Lane County is in the Plan succession class, not Remove soon. The tree is healthy now, but it will decline once EAB arrives unless it is treated. It is not failing. Decide per tree: protect the trees worth protecting, and plant successors for the rest while the ash still gives shade. When EAB is confirmed in Lane County, untreated ash moves to Remove soon.
A42: THE COSTS
A43: For one tree, treatment is usually cheaper than replacement over 15 years. An 18 in ash costs about $216 per treatment, or about $1,700 over 15 years. Removal and replacement costs about $2,800. So replacement is not a saving. Treatment also keeps the canopy. Replacement makes sense when the tree is low value, declining or badly placed, or when no one will commit to long-term treatment.
A45: PHASED REPLACEMENT — plant first, remove later
A46: Step 1 | B46: Plant the successor now, in light: outside the ash dripline or in a canopy gap.
A47: Step 2 | B47: Water it on the Establishment Water schedule. Add it to the Install Log. Copy its Install ID to the Ash Register.
...

Sheet Palette
A1: Scientific Name | B1: Common Name | C1: Genus | D1: Family | E1: Cultivar / Clone | F1: Habit | G1: Mature H x W (ft) | H1: Max Ht (ft) | I1: Summer Drought | J1: Winter-Wet / Clay | K1: Tier | L1: Grp 1 Clay | M1: Grp 2 Silt Loam | N1: Grp 3 Upland | O1: Under Wires | P1: Water Class | Q1: Sourcing 1-5 | R1: Pest / Disease Risk | S1: Spec Notes | T1: Source | U1: Review By
A2: Maclura pomifera 'White Shield' | B2: Osage Orange | C2: Maclura | D2: Moraceae | E2: 'White Shield' - thornless, fruitless male clone. VERIFY CLONE. | F2: Canopy tree · Dec | G2: 35-50 x 35-45 | H2: 50 | I2: Very High | J2: High | K2: A | L2: Yes | M2: Yes | N2: Yes | O2: No | P2: Standard | Q2: 4 | R2: Very few | S2: Near-indestructible on clay, compaction and drought. Entire value depends on getting the true clone - seedling Maclura is thorny and drops softball fruit. Inspect at the nursery. Watch for: Suckers if roots are damaged. | T2: SelecTree 536
A3: Quercus bicolor | B3: Swamp White Oak | C3: Quercus | D3: Fagaceae | E3: Straight species | F3: Canopy tree · Dec | G3: 50-60 x 50-60 | H3: 60 | I3: High | J3: Very High | K3: A | L3: Yes | M3: Yes | N3: Caution | O3: No | P3: Standard | Q3: 2 | R3: No significant regional issues | S3: Added specifically as the Oregon ash replacement. Tolerates extended winter saturation better than anything else on this list while still handling summer drought - that combination is exactly the wet-bottomland niche ash occupies and almost nothing else fills. Watch for: Acorn litter. | T3: Regional addition
A4: Quercus garryana | B4: Oregon White Oak | C4: Quercus | D4: Fagaceae | E4: Local provenance | F4: Canopy tree · Dec | G4: 50-80 x 50-80 | H4: 80 | I4: High | J4: High | K4: A | L4: Yes | M4: Yes | N4: Yes | O4: No | P4: Standard | Q4: 3 | R4: Minor oak twig blight; jumping gall wasp cosmetic | S4: The valley benchmark: evolved for exactly the wet-winter/dry-summer regime. Highest habitat value on the list. Slow establishment - do not overwater after year 3. Watch for: Acorn and leaf litter. | T4: Regional addition
A5: Quercus imbricaria | B5: Shingle Oak | C5: Quercus | D5: Fagaceae | E5: Straight species | F5: Canopy tree · Dec (marcescent) | G5: 50-60 x 50-60 | H5: 60 | I5: High | J5: High | K5: A | L5: Yes | M5: Yes | N5: Caution | O5: No | P5: Standard | Q5: 2 | R5: Few serious issues | S5: Marcescence is the whole story: excellent tall winter screen, but not for anyone who wants a tidy look. Know this before planting. Watch for: Holds dead brown leaves through winter. | T5: SelecTree 536
A6: Quercus macrocarpa | B6: Bur Oak | C6: Quercus | D6: Fagaceae | E6: Straight species | F6: Canopy tree · Dec | G6: 60-80 x 60-80 | H6: 80 | I6: High | J6: High | K6: A | L6: Yes | M6: Yes | N6: Yes | O6: No | P6: Standard | Q6: 2 | R6: No significant regional issues | S6: Strongest large-canopy option for winter-saturated clay. Tolerates compaction, seasonal flooding and drought. Slow, so plant larger stock or expect patience. Watch for: Large acorns - avoid over walks/patios. | T6: SelecTree 536
A7: Calocedrus decurrens | B7: Incense Cedar | C7: Calocedrus | D7: Cupressaceae | E7: Straight species | F7: Conifer · Evg | G7: 40-70 x 15-25 | H7: 70 | I7: High | J7: Moderate | K7: A | L7: Caution | M7: Yes | N7: Yes | O7: No | P7: Standard | Q7: 2 | R7: Generally clean; avoid saturated soil | S7: Best native tall evergreen screen. Narrow footprint suits property lines. Better drainage tolerance than most conifers but still avoid Dayton/Bashaw bottoms. | T7: Regional addition
A8: Pinus ponderosa | B8: Ponderosa Pine | C8: Pinus | D8: Pinaceae | E8: SPECIFY Willamette Valley seed source | F8: Conifer · Evg | G8: 60-100 x 25-40 | H8: 100 | I8: High | J8: High | K8: A | L8: Yes | M8: Yes | N8: Yes | O8: No | P8: Standard | Q8: 2 | R8: Sequoia pitch moth (cosmetic); avoid summer pruning | S8: Provenance is not optional: the Willamette Valley race tolerates seasonally saturated clay that interior sources will not. Confirm seed source in writing on the PO. Watch for: Needle and cone litter. | T8: Regional addition
A9: Amelanchier alnifolia | B9: Western Serviceberry | C9: Amelanchier | D9: Rosaceae | E9: Straight species | F9: Large shrub / small tree · Dec | G9: 6-15 x 6-12 | H9: 15 | I9: High | J9: Moderate | K9: A | L9: Caution | M9: Yes | N9: Yes | O9: Yes | P9: Standard | Q9: 2 | R9: Rust (cedar-apple type) near junipers; fireblight | S9: Spring bloom, edible fruit, fall color. Not for true bottomland; use on Group 1 only on a berm. | T9: OSU EM 8721
A10: Arbutus unedo | B10: Strawberry Tree | C10: Arbutus | D10: Ericaceae | E10: 'Compacta' / 'Elfin King' hedging; 'Marina' as small tree | F10: Large shrub / small tree · Evg | G10: 8-25 x 8-25 | H10: 25 | I10: High | J10: Moderate | K10: A | L10: Caution | M10: Yes | N10: Yes | O10: Caution | P10: Standard | Q10: 1 | R10: Root rot in saturated soil; otherwise clean | S10: Best hedge option from the source list and a strong multi-season performer. Keep off valley-bottom clay or plant on a raised berm. Site away from patios and light-colored paving. Watch for: Fruit drop stains hardscape. | T10: SelecTree 536
A11: Cotinus coggygria | B11: Smokebush | C11: Cotinus | D11: Anacardiaceae | E11: 'Royal Purple', 'Grace' (larger) | F11: Large shrub / small tree · Dec | G11: 10-15 x 10-15 | H11: 15 | I11: Very High | J11: Moderate | K11: A | L11: Caution | M11: Yes | N11: Yes | O11: Yes | P11: Standard | Q11: 1 | R11: Verticillium wilt on poorly drained sites | S11: The purple-foliage replacement for a flowering plum. Genuinely drought-hardy, unlike the Prunus it replaces. Can be coppiced for larger leaf color or grown on as a small multi-stem tree. | T11: Great Plant Picks
A12: Maackia amurensis | B12: Amur Maackia | C12: Maackia | D12: Fabaceae | E12: Straight species | F12: Small tree · Dec | G12: 20-30 x 20-30 | H12: 30 | I12: High | J12: Moderate | K12: A | L12: Yes | M12: Yes | N12: Caution | O12: Yes | P12: Standard | Q12: 3 | R12: No significant issues | S12: Borderline A/B - avoid true bottomland positions. Nitrogen fixer, tolerates poor and compacted soil, coppery peeling bark. One of few genuine under-wire options here. | T12: SelecTree 536
A13: Malus fusca | B13: Pacific Crabapple | C13: Malus | D13: Rosaceae | E13: Straight species, local seed source | F13: Small tree · Dec | G13: 15-30 x 15-25 | H13: 30 | I13: Moderate | J13: Very High | K13: A | L13: Yes | M13: Yes | N13: Caution | O13: Yes | P13: Standard | Q13: 3 | R13: Apple scab and rust possible; usually minor | S13: Native wetland-edge tree. One of very few non-oak trees for Group 1 clay. Thorny spurs; small fruit feeds birds. Center-row tree in a wet-site hedgerow. | T13: OSU EM 8721
... A32: Pistacia chinensis | B32: Chinese Pistache | C32: Pistacia | D32: Anacardiaceae | E32: Male clones only ('Keith Davey') | F32: Canopy tree · Dec | G32: 30-50 x 30-40 | H32: 50 | I32: High | J32: Low | K32: B | L32: No | M32: Yes | N32: Yes | O32: No | P32: Standard | Q32: 2 | R32: Verticillium wilt on poorly drained sites | S32: Sharp drainage is mandatory. Also runs slower and colors less reliably here than in its California trials - expect less reliable fall color than in California. Watch for: Female trees fruit heavily. | T32: SelecTree 536
A33: Quercus kelloggii | B33: California Black Oak | C33: Quercus | D33: Fagaceae | E33: SW Oregon provenance preferred | F33: Canopy tree · Dec | G33: 50-80 x 40-70 | H33: 80 | I33: High | J33: Low | K33: B | L33: No | M33: Caution | N33: Yes | O33: No | P33: Drought-adapted | Q33: 4 | R33: Known Phytophthora ramorum host (SOD quarantine is Curry Co., not Lane) | S33: Credible assisted-migration candidate. Taprooted and transplant-sensitive: plant small container stock or direct seed, never large B&B. Upland sites only. Watch for: Acorn and leaf litter. Check the sudden oak death quarantine boundary each year. | T33: SelecTree 536 | U33: 46447
A34: Quercus wislizeni | B34: Interior Live Oak | C34: Quercus | D34: Fagaceae | E34: Straight species | F34: Canopy tree · Evg | G34: 30-60 x 30-60 | H34: 60 | I34: High | J34: Low | K34: B | L34: No | M34: Caution | N34: Yes | O34: No | P34: Drought-adapted | Q34: 5 | R34: Generally clean | S34: Upland/well-drained only. Sourcing is the binding constraint - Portland reports evergreen oaks are hard to obtain in usable caliper. Arrange stock with a grower 2-3 years ahead. Watch for: Year-round leaf drop. | T34: SelecTree 536
A35: Tilia tomentosa | B35: Silver Linden | C35: Tilia | D35: Malvaceae | E35: 'Sterling' | F35: Canopy tree · Dec | G35: 50-70 x 40-50 | H35: 70 | I35: High | J35: High | K35: B | L35: Caution | M35: Yes | N35: No | O35: No | P35: Standard | Q35: 2 | R35: PRIME Japanese beetle host. ODA eradication funded only through the 2027 crop year; Lane Co. clear as of 2025 detections. | S35: Climatically fine, strategically risky. It is a 50-year tree facing a pest whose control depends on state funding renewed every two years. Use it only if you accept that risk. Watch for: Honeydew (less than other Tilia). Review when state Japanese beetle funding is next decided. | T35: SelecTree 536 | U35: 46569
A36: Hesperocyparis arizonica | B36: Arizona Cypress | C36: Hesperocyparis | D36: Cupressaceae | E36: 'Blue Ice', 'Carolina Sapphire' | F36: Conifer · Evg | G36: 30-50 x 15-25 | H36: 50 | I36: Very High | J36: Low | K36: B | L36: No | M36: Caution | N36: Yes | O36: No | P36: Drought-adapted | Q36: 2 | R36: Seiridium and Botryosphaeria canker in cool wet springs; Phytophthora in wet soil | S36: Fastest screen on the list, and the one most likely to fail. Restrict to sharply drained, sunny, well-ventilated sites. Never plant as a solid single-species hedge row - canker will take the whole run. | T36: SelecTree 536
A37: Salix hookeriana | B37: Hooker's Willow | C37: Salix | D37: Salicaceae | E37: Straight species; plant from live stakes | F37: Large shrub / small tree · Dec | G37: 10-25 x 10-20 | H37: 25 | I37: Moderate | J37: Very High | K37: B | L37: Yes | M37: Caution | N37: No | O37: No | P37: Standard | Q37: 1 | R37: Willow borers, rust, canker | S37: Aggressive roots. Keep 50+ ft from sewer lines, drains and foundations. Rural swales and pond edges only. Cheap and fast from cuttings. | T37: OSU EM 8721
A38: Arctostaphylos densiflora | B38: Vine Hill Manzanita | C38: Arctostaphylos | D38: Ericaceae | E38: 'Howard McMinn' - the reliable clone here | F38: Shrub · Evg | G38: 5-7 x 6-8 | H38: 7 | I38: Very High | J38: Low | K38: B | L38: No | M38: Caution | N38: Yes | O38: Yes | P38: Drought-adapted | Q38: 3 | R38: Phytophthora and branch dieback in wet or irrigated soil | S38: Superb on Group 3 slopes, reliably fatal in Group 1 bottoms. Never install on drip irrigation past year 2. Berm and use coarse mineral mulch, not bark. | T38: Great Plant Picks
A39: Ceanothus thyrsiflorus | B39: Blueblossom | C39: Ceanothus | D39: Rhamnaceae | E39: 'Victoria' is the hardiest reliable clone | F39: Shrub / hedge · Evg | G39: 6-12 x 6-12 | H39: 12 | I39: Very High | J39: Low | K39: B | L39: No | M39: Caution | N39: Yes | O39: Yes | P39: Drought-adapted | Q39: 2 | R39: Root rot with summer water; hard-freeze damage in severe winters | S39: Plan on a 10-15 year lifespan and no summer water. Fast and spectacular, but not a permanent plant; do not use it where a long-lived hedge is needed. Watch for: Short-lived. | T39: Great Plant Picks
A40: Cistus x hybridus | B40: White Rockrose | C40: Cistus | D40: Cistaceae | E40: Also C. x purpureus | F40: Shrub · Evg | G40: 2-4 x 4-6 | H40: 4 | I40: Very High | J40: Very Low | K40: B | L40: No | M40: Caution | N40: Yes | O40: Yes | P40: Drought-adapted | Q40: 1 | R40: Root rot in winter-wet soil; does not respond to hard pruning | S40: Group 3 slopes and hell strips only. Cannot be renovated by cutting back into old wood - plan on replacing it at 10-12 years. Watch for: Short-lived; gets leggy. | T40: Great Plant Picks
A41: Salvia rosmarinus | B41: Rosemary | C41: Salvia | D41: Lamiaceae | E41: 'Tuscan Blue' upright; 'Huntington Carpet' prostrate | F41: Shrub / hedge · Evg | G41: 2-5 x 2-4 | H41: 5 | I41: Very High | J41: Very Low | K41: B | L41: No | M41: Caution | N41: Yes | O41: Yes | P41: Drought-adapted | Q41: 1 | R41: Root rot on heavy soil | S41: Only on sharply drained sites. Popular, but on Group 1 clay use wax myrtle instead. Watch for: Gets woody and open with age. | T41: Great Plant Picks
A42: Aesculus x carnea | B42: Red Horsechestnut | C42: Aesculus | D42: Sapindaceae | E42: 'Briotii', 'Fort McNair' | F42: Canopy tree · Dec | G42: 30-40 x 30-40 | H42: 40 | I42: Low | J42: Moderate | K42: C | L42: Caution | M42: Caution | N42: No | O42: No | P42: Standard | Q42: 2 | R42: Guignardia leaf blotch; heat and drought scorch | S42: Fails the low-input standard. Scorches by August in the valley without extra water. Not recommended. Watch for: Fruit litter. | T42: SelecTree 536
A43: Thuja plicata | B43: Western Redcedar | C43: Thuja | D43: Cupressaceae | E43: — | F43: Conifer · Evg | G43: 50-70 x 15-25 | H43: 70 | I43: Low | J43: High | K43: C | L43: Caution | M43: Caution | N43: No | O43: No | P43: Standard | Q43: 1 | R43: Drought dieback now common in the valley | S43: Listed in EM 8721. Declining in valley summers. Only on shaded, moist Group 2 sites with long-term water. Not a low-input plant. | T43: OSU EM 8721
A44: Viburnum opulus | B44: Highbush Cranberry | C44: Viburnum | D44: Viburnaceae | E44: Native var. americanum ONLY | F44: Shrub · Dec | G44: 8-12 x 8-12 | H44: 12 | I44: Moderate | J44: High | K44: C | L44: Caution | M44: Caution | N44: No | O44: Yes | P44: Standard | Q44: 3 | R44: Viburnum leaf beetle; European form spreads by birds | S44: Listed in EM 8721. Nurseries often sell the European form, which spreads. Buy only the native variety, or do not use it. | T44: OSU EM 8721
A45: Fraxinus latifolia | B45: Oregon Ash | C45: Fraxinus | D45: Oleaceae | E45: — | F45: Canopy tree · Dec | G45: 40-80 x 30-50 | H45: 80 | I45: Moderate | J45: Very High | K45: Reject | L45: No | M45: No | N45: No | O45: No | P45: Standard | Q45: 1 | R45: Emerald ash borer confirmed in Oregon | S45: Listed in EM 8721 as wet-tolerant. It is the tree being replaced. Use Quercus bicolor or Malus fusca (natives only on riparian sites). For existing ash, see the Ash and EAB page. Review each year against EAB spread, and if EAB-resistant Oregon ash stock becomes available. | T45: OSU EM 8721 | U45: 46447
A46: Prunus avium | B46: Sweet Cherry | C46: Prunus | D46: Rosaceae | E46: — | F46: Canopy tree · Dec | G46: 30-40 x 25-35 | H46: 40 | I46: Moderate | J46: Moderate | K46: Reject | L46: No | M46: No | N46: No | O46: No | P46: Standard | Q46: 1 | R46: Bird-dispersed; spreads into woodland | S46: Listed in EM 8721, but it is a common invader of Willamette Valley oak woodland. Do not plant. | T46: OSU EM 8721
A47: Robinia pseudoacacia | B47: Black Locust | C47: Robinia | D47: Fabaceae | E47: — | F47: Canopy tree · Dec | G47: 40-60 x 30-40 | H47: 60 | I47: Very High | J47: High | K47: Reject | L47: No | M47: No | N47: No | O47: No | P47: Standard | Q47: 1 | R47: Locust borer; aggressive root suckers | S47: Listed in EM 8721. Suckers widely and naturalizes along valley roads and streams. Thorny. Do not plant. | T47: OSU EM 8721
A48: x Chitalpa tashkentensis | B48: Chitalpa | C48: Chitalpa | D48: Bignoniaceae | E48: 'Pink Dawn', 'Morning Cloud' | F48: Small tree · Dec | G48: 20-30 x 20-30 | H48: 30 | I48: High | J48: Very Low | K48: Reject | L48: No | M48: No | N48: Caution | O48: Yes | P48: Standard | Q48: 2 | R48: Powdery mildew; Xylella-associated decline | S48: A desert hybrid requiring heat and low humidity. Wrong climate, wrong soil, wrong lifespan for a long-term planting. Do not plant. Watch for: Weak wood; short-lived (15-25 yrs). | T48: SelecTree 536
A49: Elaeagnus umbellata | B49: Autumn Olive | C49: Elaeagnus | D49: Elaeagnaceae | E49: — | F49: Large shrub · Dec | G49: 12-20 x 12-20 | H49: 20 | I49: Very High | J49: Moderate | K49: Reject | L49: No | M49: No | N49: No | O49: No | P49: Standard | Q49: 1 | R49: Bird-dispersed; invasive in much of the US | S49: Listed in EM 8721 as an edible hedgerow plant. Widely invasive. Do not plant. | T49: OSU EM 8721

Sheet Hedgerow Design
A1: HEDGEROW DESIGN — MIXED PLANTINGS
A2: Based on OSU Extension EM 8721, A Guide to Hedgerows (Monnette and Hobbs; revised 2020, reviewed 2023). A hedgerow is a mixed, layered planting in place of a single-species hedge. It gives screening, habitat and pest resilience in one planting. Use it where the site has room.
A4: QUANTITY CALCULATOR
A5: Hedgerow length (ft) | B5: 100 | C5: Measure along the line.
A6: Number of rows | B6: 2 | C6: 2 for residential lines; 3 or more where width allows.
A7: Spacing in the row (ft) | B7: 6 | C7: EM 8721: 6-8 ft. Use 4-6 ft for a faster screen.
A8: Spacing between rows (ft) | B8: 8 | C8: EM 8721: 8-10 ft.
A9: Plants per row | B9: =ROUNDUP($B$5/$B$7,0)+1 -> 18 | C9: Staggered rows use the same count.
A10: Total plants | B10: =B9*$B$6 -> 36
A11: Approximate width needed (ft) | B11: =($B$6-1)*$B$8+$B$7 -> 14 | C11: Row spacing plus half a plant spread each side.
A12: Most rose-family plants allowed (30%) | B12: =ROUNDDOWN(B10*0.3,0) -> 10 | C12: Malus, Physocarpus, Oemleria, Rosa, Spiraea, Amelanchier, Holodiscus.
A13: Most Tier B plants allowed | B13: =ROUNDDOWN(B10*'Start Here'!$B$9,0) -> 3 | C13: From the Tier B cap in Start Here settings.
A14: Evergreens for winter screen (1 in 3 of one row) | B14: =ROUNDUP(B9/3,0) -> 6 | C14: Usually Morella californica in the screen row.
A16: DESIGN STANDARD — EM 8721 AND LOCAL ADAPTATION
A17: Parameter | B17: EM 8721 guidance | C17: Local adaptation
A18: Rows | B18: 4 or more rows is best. One row still gives some benefit. | C18: Residential lines: 2 staggered rows is the practical minimum. Use 3 or more on rural-fringe, commercial and HOA common areas.
A19: Width | B19: Wider than 20 ft works best for wildlife. A 20 ft hedgerow can hold 2 shrub rows around 1 tree row. | C19: Most residential lines give 6-12 ft. Do not expect much habitat value below about 10 ft. Use the full width where the land exists.
A20: Spacing | B20: 6-8 ft apart in the row. Rows 8-10 ft apart. | C20: Stagger the rows. Tighten to 4-6 ft in the row for a faster screen; this adds stock cost.
A21: Layering | B21: Tallest plants in the center row. Shorter plants between and along the edges. | C21: On a property line, put the tallest row on the side of the view to block. Keep the low row toward the area people use.
A22: Wind | B22: Plant rows across the prevailing wind. 40-50% density can cut wind speed by up to 75%. Winter windbreak: 2 evergreen rows plus 1 deciduous row. | C22: Valley storm winds come mostly from the south and southwest in winter. Summer winds come mostly from the north. Orient windbreaks to the season that matters on the site.
A23: Mulch and weeds | B23: At least 3 in of mulch. Keep a 6-8 ft mowed strip around the planting. | C23: 3-4 in of arborist chip. This agrees with the guide.
A24: Fire | B24: The mowed strip also serves as fire protection. | C24: Keep hedgerows out of the 0-5 ft zone around structures. Do not put resinous evergreens next to buildings. Apply defensible-space standards on wildland-edge sites.
A25: Animals | B25: Hardware cloth for beaver and nutria. Trunk guards for voles and mice. | C25: Use the Field Card deer rating. Install guards at planting, not as a later fix.
A26: Planting time | B26: Fall planting in mild climates. Roots grow through the winter rains. | C26: Agrees with the October-March planting window. Fall is preferred.
A27: Irrigation | B27: Year 1: weekly. Year 2: every 2 weeks. Year 3: monthly. Water deeply. Most hedgerows fail without water in the first years. | C27: Agrees with the Group 2 intervals (7 / 14 / 28 days). Establishment Water adds the Group 1 and Group 3 changes.
A28: Timeline | B28: 4-8 years to establish. 30+ years to reach maturity. | C28: Watering ends after year 3, but a hedgerow does not close until year 4-8. Keep up weed and edge control through the training tier (years 3-10).
A29: Diversity | B29: Plant a mix of species so one pest or disease cannot take the whole planting. | C29: Same rule as Program Review. One hedgerow can hold 6-10 species.
A31: TEMPLATE A — GROUP 1 WET CLAY, 3 ROWS, ABOUT 20 FT WIDE
A32: Row | B32: Species (pick 2-4 per row) | C32: Notes
A33: Center — tall | B33: Malus fusca; Quercus garryana or Q. bicolor (1 per 25-30 ft only); Salix hookeriana (rural sites only) | C33: Do not fill the center row with oak. Use crabapple between oaks.
A34: Middle — screen | B34: Morella californica; Physocarpus capitatus; Sambucus cerulea; Cornus sericea; Oemleria cerasiformis | C34: Put Morella in every 2nd or 3rd slot. It is the only evergreen in this template. Without it the row is open in winter.
A35: Edge — low | B35: Spiraea douglasii; Rosa nutkana; Symphoricarpos albus; Lonicera involucrata | C35: All spread by roots or layering. Give them a defined strip and a mowed edge.
A36: FAMILY LIMIT: Malus, Physocarpus, Oemleria, Rosa and Spiraea are all rose family (Rosaceae). Keep them to 3 of every 10 plants or fewer. Fill the rest with Morella, Cornus, Sambucus, Lonicera, Symphoricarpos and oak. A test mix built mostly from rose-family natives reached about 70% one family.
A38: TEMPLATE B — NARROW RESIDENTIAL, 2 STAGGERED ROWS, 8-10 FT WIDE
A39: Row | B39: Species | C39: Notes
A40: Back row | B40: Alternate Morella californica with Physocarpus capitatus (Groups 1-2) or Osmanthus x burkwoodii (Groups 2-3) | C40: Evergreen share gives winter screening. This is the direct replacement for a laurel or arborvitae hedge.
A41: Front row | B41: Ribes sanguineum; Cornus sericea 'Isanti'; Berberis aquifolium; Rosa nutkana only away from paths | C41: Mix for flowers, fruit and winter stem color. Informal. Not for a sheared look.
A43: WHERE IT FITS
A44: 1. | B44: Consider a hedgerow for laurel, arborvitae and photinia replacements. The site needs 8 ft of width or more.
A45: 2. | B45: Best fits rural-fringe, commercial, HOA common areas and larger lots. These have the width and the longer horizon.
...

Sheet Establishment Water
A1: ESTABLISHMENT WATERING — YEARS 1-3
A2: Survival is decided in the first three dry seasons, not at planting. 'Drought-adapted' never means 'no water while establishing'. Write this plan down: whoever waters gets a printed copy (Watering Plan tab), and any replacement guarantee should refer to it.
A4: THE SEASON
A5: The watering season runs about June 15 to October 15 (length set in Start Here). Outside that window, extra water is not needed in a normal year. On Group 1 clay it does harm. Do not leave systems running into November.
A7: INTERVAL — DAYS BETWEEN WATERINGS (standard plants)
B8: Group 1 clay | C8: Group 2 silt loam | D8: Group 3 upland
A9: Year 1 | B9: 10 | C9: 7 | D9: 5
A10: Year 2 | B10: 21 | C10: 14 | D10: 10
A11: Year 3 | B11: 30 | C11: 28 | D11: 21
A12: Clay holds water, so intervals stretch; the risk there is root rot, not drought. Group 3 soils are shallow and dry out fast, so intervals shorten. Always water deep and slow. The goal is to pull roots down and out of the planting hole.
A14: VOLUME AND METHOD
A15: Trees | B15: 10 gallons per inch of trunk caliper each time. A 2 in tree takes 20 gallons.
A16: Shrubs | B16: About 1 gallon per gallon of container size. A 5 gal shrub takes about 5 gallons.
A17: Delivery | B17: Slow release only: gator bag, drip ring, or a hose on a trickle. Sprinklers and short spray cycles wet the mulch and nothing else. Build a 3 in soil ring at the root ball edge on flat sites.
A18: Mulch | B18: 3-4 in coarse arborist chip, pulled clear of the trunk flare, out to the dripline. Renew in years 2 and 3. Mulch does more for survival than extra watering.
A20: DROUGHT-ADAPTED OVERRIDE — READ THIS ONE
A21: The Palette 'Water Class' column marks drought-adapted species (manzanita, ceanothus, rockrose, rosemary, Arizona cypress, silktassel and the California oaks). They run 1.5x the interval in years 1-2 and get NO extra water from year 3 on. Summer water past year 2 kills these plants more often than drought does. Never put them on a drip zone. Never add them to an existing irrigation schedule. If no one will commit to shutting the water off, choose a Standard species.
A23: HEAT EVENT OVERRIDE
A24: Three or more days in a row above 100 F: water every planting once, whatever the schedule or year. This includes stock in years 4-5. Water in the early morning or evening. The 2021 heat dome killed established plants that were fine the week before. Track these as separate watering events.
A26: CALCULATOR — ONE SITE
A27: Enter one site. Pick each plant from the dropdown; its water class fills in from the Palette. Visits are counted once per site, so mixed plantings are not double-counted. Drought-adapted plants get water on a longer cycle during the same visits.
A28: Soil group (1 / 2 / 3) | B28: 2 | C28: From the Field Card.
A29: Labor hours per watering visit | B29: 1.5 | C29: Whole site, travel included. Placeholder.
A30: Dry season length (days) | B30: ='Start Here'!$B$8 -> 122 | C30: From Start Here settings.
A31: Labor rate ($/hour) | B31: ='Start Here'!$B$6 -> 150 | C31: From Start Here settings.
A33: Plant (from Palette) | B33: Water class | C33: Caliper (in) | D33: Container (gal) | E33: Count | F33: Gal each, per watering | G33: Yr 1 waterings | H33: Yr 2 waterings | I33: Yr 3 waterings | J33: 3-yr gallons
A34: Morella californica | B34: =IF($A34="","",IFERROR(INDEX(Palette!$P$2:$P$151,MATCH($A34,Palette!$A$2:$A$151,0)),"Standard")) -> Standard | C34: 0 | D34: 5 | E34: 25 | F34: =IF(N($E34)=0,0,IF(N($C34)>0,$C34*10,N($D34))) -> 5 | G34: =IF(N($E34)=0,0,ROUNDUP($B$30/IF($B34="Drought-adapted",ROUND(INDEX($B$9:$D$11,1,$B$28)*1.5,0),INDEX($B$9:$D$11,1,$B$28)),0)) -> 18 | H34: =IF(N($E34)=0,0,ROUNDUP($B$30/IF($B34="Drought-adapted",ROUND(INDEX($B$9:$D$11,2,$B$28)*1.5,0),INDEX($B$9:$D$11,2,$B$28)),0)) -> 9 | I34: =IF(OR(N($E34)=0,$B34="Drought-adapted"),0,ROUNDUP($B$30/INDEX($B$9:$D$11,3,$B$28),0)) -> 5 | J34: =F34*N(E34)*(G34+H34+I34) -> 4000
B35: =IF($A35="","",IFERROR(INDEX(Palette!$P$2:$P$151,MATCH($A35,Palette!$A$2:$A$151,0)),"Standard")) | F35: =IF(N($E35)=0,0,IF(N($C35)>0,$C35*10,N($D35))) -> 0 | G35: =IF(N($E35)=0,0,ROUNDUP($B$30/IF($B35="Drought-adapted",ROUND(INDEX($B$9:$D$11,1,$B$28)*1.5,0),INDEX($B$9:$D$11,1,$B$28)),0)) -> 0 | H35: =IF(N($E35)=0,0,ROUNDUP($B$30/IF($B35="Drought-adapted",ROUND(INDEX($B$9:$D$11,2,$B$28)*1.5,0),INDEX($B$9:$D$11,2,$B$28)),0)) -> 0 | I35: =IF(OR(N($E35)=0,$B35="Drought-adapted"),0,ROUNDUP($B$30/INDEX($B$9:$D$11,3,$B$28),0)) -> 0 | J35: =F35*N(E35)*(G35+H35+I35) -> 0
B36: =IF($A36="","",IFERROR(INDEX(Palette!$P$2:$P$151,MATCH($A36,Palette!$A$2:$A$151,0)),"Standard")) | F36: =IF(N($E36)=0,0,IF(N($C36)>0,$C36*10,N($D36))) -> 0 | G36: =IF(N($E36)=0,0,ROUNDUP($B$30/IF($B36="Drought-adapted",ROUND(INDEX($B$9:$D$11,1,$B$28)*1.5,0),INDEX($B$9:$D$11,1,$B$28)),0)) -> 0 | H36: =IF(N($E36)=0,0,ROUNDUP($B$30/IF($B36="Drought-adapted",ROUND(INDEX($B$9:$D$11,2,$B$28)*1.5,0),INDEX($B$9:$D$11,2,$B$28)),0)) -> 0 | I36: =IF(OR(N($E36)=0,$B36="Drought-adapted"),0,ROUNDUP($B$30/INDEX($B$9:$D$11,3,$B$28),0)) -> 0 | J36: =F36*N(E36)*(G36+H36+I36) -> 0
B37: =IF($A37="","",IFERROR(INDEX(Palette!$P$2:$P$151,MATCH($A37,Palette!$A$2:$A$151,0)),"Standard")) | F37: =IF(N($E37)=0,0,IF(N($C37)>0,$C37*10,N($D37))) -> 0 | G37: =IF(N($E37)=0,0,ROUNDUP($B$30/IF($B37="Drought-adapted",ROUND(INDEX($B$9:$D$11,1,$B$28)*1.5,0),INDEX($B$9:$D$11,1,$B$28)),0)) -> 0 | H37: =IF(N($E37)=0,0,ROUNDUP($B$30/IF($B37="Drought-adapted",ROUND(INDEX($B$9:$D$11,2,$B$28)*1.5,0),INDEX($B$9:$D$11,2,$B$28)),0)) -> 0 | I37: =IF(OR(N($E37)=0,$B37="Drought-adapted"),0,ROUNDUP($B$30/INDEX($B$9:$D$11,3,$B$28),0)) -> 0 | J37: =F37*N(E37)*(G37+H37+I37) -> 0
B38: =IF($A38="","",IFERROR(INDEX(Palette!$P$2:$P$151,MATCH($A38,Palette!$A$2:$A$151,0)),"Standard")) | F38: =IF(N($E38)=0,0,IF(N($C38)>0,$C38*10,N($D38))) -> 0 | G38: =IF(N($E38)=0,0,ROUNDUP($B$30/IF($B38="Drought-adapted",ROUND(INDEX($B$9:$D$11,1,$B$28)*1.5,0),INDEX($B$9:$D$11,1,$B$28)),0)) -> 0 | H38: =IF(N($E38)=0,0,ROUNDUP($B$30/IF($B38="Drought-adapted",ROUND(INDEX($B$9:$D$11,2,$B$28)*1.5,0),INDEX($B$9:$D$11,2,$B$28)),0)) -> 0 | I38: =IF(OR(N($E38)=0,$B38="Drought-adapted"),0,ROUNDUP($B$30/INDEX($B$9:$D$11,3,$B$28),0)) -> 0 | J38: =F38*N(E38)*(G38+H38+I38) -> 0
B39: =IF($A39="","",IFERROR(INDEX(Palette!$P$2:$P$151,MATCH($A39,Palette!$A$2:$A$151,0)),"Standard")) | F39: =IF(N($E39)=0,0,IF(N($C39)>0,$C39*10,N($D39))) -> 0 | G39: =IF(N($E39)=0,0,ROUNDUP($B$30/IF($B39="Drought-adapted",ROUND(INDEX($B$9:$D$11,1,$B$28)*1.5,0),INDEX($B$9:$D$11,1,$B$28)),0)) -> 0 | H39: =IF(N($E39)=0,0,ROUNDUP($B$30/IF($B39="Drought-adapted",ROUND(INDEX($B$9:$D$11,2,$B$28)*1.5,0),INDEX($B$9:$D$11,2,$B$28)),0)) -> 0 | I39: =IF(OR(N($E39)=0,$B39="Drought-adapted"),0,ROUNDUP($B$30/INDEX($B$9:$D$11,3,$B$28),0)) -> 0 | J39: =F39*N(E39)*(G39+H39+I39) -> 0
A41: Site watering visits | G41: =MAX(G34:G39) -> 18 | H41: =MAX(H34:H39) -> 9 | I41: =MAX(I34:I39) -> 5 | J41: =SUM(G41:I41) -> 32
A42: Gallons applied | G42: =SUMPRODUCT($F$34:$F$39,$E$34:$E$39,G34:G39) -> 2250 | H42: =SUMPRODUCT($F$34:$F$39,$E$34:$E$39,H34:H39) -> 1125 | I42: =SUMPRODUCT($F$34:$F$39,$E$34:$E$39,I34:I39) -> 625 | J42: =SUM(G42:I42) -> 4000
A43: Labor hours | G43: =G41*$B$29 -> 27 | H43: =H41*$B$29 -> 13.5 | I43: =I41*$B$29 -> 7.5 | J43: =SUM(G43:I43) -> 48
A44: Watering cost if hired out | G44: =G43*$B$31 -> 4050 | H44: =H43*$B$31 -> 2025 | I44: =I43*$B$31 -> 1125 | J44: =SUM(G44:I44) -> 7200
A45: The bold 3-year total (right) feeds the 'Hired watering' line in Conversion Economics. Reliable watering is the biggest survival factor you control.
A47: WHAT TO HAND OVER
A48: At install | B48: The Watering Plan tab, printed: dates, gallons per plant, method and the shut-off date. Not verbal instructions.
A49: On the schedule | B49: Each watering visit as a scheduled item, if a contractor waters.
...

Sheet Watering Plan
A1: YOUR NEW PLANTING — WATERING PLAN
A2: Please keep this page. Any replacement guarantee depends on following it.
A3: Owner
A4: Site address
A5: Install date
A6: Watering done by
A7: Contact
A8: Soil group | B8: ='Establishment Water'!$B$28 -> 2
A9: Stop all watering after | B9: =IF($B$5="","(enter install date)",DATE(IF($B$5="","",YEAR($B$5)+IF(MONTH($B$5)>=10,1,0))+2,10,15)) -> (enter install date)
A11: SCHEDULE — water every ... days, June 15 to October 15
A12: Plant | B12: Gallons each plant, each time | C12: =IF($B$5="","Summer "&1,"Summer "&(IF($B$5="","",YEAR($B$5)+IF(MONTH($B$5)>=10,1,0))+0)) -> Summer 1 | D12: =IF($B$5="","Summer "&2,"Summer "&(IF($B$5="","",YEAR($B$5)+IF(MONTH($B$5)>=10,1,0))+1)) -> Summer 2 | E12: =IF($B$5="","Summer "&3,"Summer "&(IF($B$5="","",YEAR($B$5)+IF(MONTH($B$5)>=10,1,0))+2)) -> Summer 3
A13: =IF('Establishment Water'!$A34="","",'Establishment Water'!$A34) -> Morella californica | B13: =IF($A13="","",'Establishment Water'!$F34) -> 5 | C13: =IF($A13="","",IF('Establishment Water'!$B34="Drought-adapted",ROUND(INDEX('Establishment Water'!$B$9:$D$11,1,'Establishment Water'!$B$28)*1.5,0),INDEX('Establishment Water'!$B$9:$D$11,1,'Establishment Water'!$B$28))&" days") -> 7 days | D13: =IF($A13="","",IF('Establishment Water'!$B34="Drought-adapted",ROUND(INDEX('Establishment Water'!$B$9:$D$11,2,'Establishment Water'!$B$28)*1.5,0),INDEX('Establishment Water'!$B$9:$D$11,2,'Establishment Water'!$B$28))&" days") -> 14 days | E13: =IF($A13="","",IF('Establishment Water'!$B34="Drought-adapted","No water",INDEX('Establishment Water'!$B$9:$D$11,3,'Establishment Water'!$B$28)&" days")) -> 28 days
A14: =IF('Establishment Water'!$A35="","",'Establishment Water'!$A35) | B14: =IF($A14="","",'Establishment Water'!$F35) | C14: =IF($A14="","",IF('Establishment Water'!$B35="Drought-adapted",ROUND(INDEX('Establishment Water'!$B$9:$D$11,1,'Establishment Water'!$B$28)*1.5,0),INDEX('Establishment Water'!$B$9:$D$11,1,'Establishment Water'!$B$28))&" days") | D14: =IF($A14="","",IF('Establishment Water'!$B35="Drought-adapted",ROUND(INDEX('Establishment Water'!$B$9:$D$11,2,'Establishment Water'!$B$28)*1.5,0),INDEX('Establishment Water'!$B$9:$D$11,2,'Establishment Water'!$B$28))&" days") | E14: =IF($A14="","",IF('Establishment Water'!$B35="Drought-adapted","No water",INDEX('Establishment Water'!$B$9:$D$11,3,'Establishment Water'!$B$28)&" days"))
A15: =IF('Establishment Water'!$A36="","",'Establishment Water'!$A36) | B15: =IF($A15="","",'Establishment Water'!$F36) | C15: =IF($A15="","",IF('Establishment Water'!$B36="Drought-adapted",ROUND(INDEX('Establishment Water'!$B$9:$D$11,1,'Establishment Water'!$B$28)*1.5,0),INDEX('Establishment Water'!$B$9:$D$11,1,'Establishment Water'!$B$28))&" days") | D15: =IF($A15="","",IF('Establishment Water'!$B36="Drought-adapted",ROUND(INDEX('Establishment Water'!$B$9:$D$11,2,'Establishment Water'!$B$28)*1.5,0),INDEX('Establishment Water'!$B$9:$D$11,2,'Establishment Water'!$B$28))&" days") | E15: =IF($A15="","",IF('Establishment Water'!$B36="Drought-adapted","No water",INDEX('Establishment Water'!$B$9:$D$11,3,'Establishment Water'!$B$28)&" days"))
A16: =IF('Establishment Water'!$A37="","",'Establishment Water'!$A37) | B16: =IF($A16="","",'Establishment Water'!$F37) | C16: =IF($A16="","",IF('Establishment Water'!$B37="Drought-adapted",ROUND(INDEX('Establishment Water'!$B$9:$D$11,1,'Establishment Water'!$B$28)*1.5,0),INDEX('Establishment Water'!$B$9:$D$11,1,'Establishment Water'!$B$28))&" days") | D16: =IF($A16="","",IF('Establishment Water'!$B37="Drought-adapted",ROUND(INDEX('Establishment Water'!$B$9:$D$11,2,'Establishment Water'!$B$28)*1.5,0),INDEX('Establishment Water'!$B$9:$D$11,2,'Establishment Water'!$B$28))&" days") | E16: =IF($A16="","",IF('Establishment Water'!$B37="Drought-adapted","No water",INDEX('Establishment Water'!$B$9:$D$11,3,'Establishment Water'!$B$28)&" days"))
A17: =IF('Establishment Water'!$A38="","",'Establishment Water'!$A38) | B17: =IF($A17="","",'Establishment Water'!$F38) | C17: =IF($A17="","",IF('Establishment Water'!$B38="Drought-adapted",ROUND(INDEX('Establishment Water'!$B$9:$D$11,1,'Establishment Water'!$B$28)*1.5,0),INDEX('Establishment Water'!$B$9:$D$11,1,'Establishment Water'!$B$28))&" days") | D17: =IF($A17="","",IF('Establishment Water'!$B38="Drought-adapted",ROUND(INDEX('Establishment Water'!$B$9:$D$11,2,'Establishment Water'!$B$28)*1.5,0),INDEX('Establishment Water'!$B$9:$D$11,2,'Establishment Water'!$B$28))&" days") | E17: =IF($A17="","",IF('Establishment Water'!$B38="Drought-adapted","No water",INDEX('Establishment Water'!$B$9:$D$11,3,'Establishment Water'!$B$28)&" days"))
A18: =IF('Establishment Water'!$A39="","",'Establishment Water'!$A39) | B18: =IF($A18="","",'Establishment Water'!$F39) | C18: =IF($A18="","",IF('Establishment Water'!$B39="Drought-adapted",ROUND(INDEX('Establishment Water'!$B$9:$D$11,1,'Establishment Water'!$B$28)*1.5,0),INDEX('Establishment Water'!$B$9:$D$11,1,'Establishment Water'!$B$28))&" days") | D18: =IF($A18="","",IF('Establishment Water'!$B39="Drought-adapted",ROUND(INDEX('Establishment Water'!$B$9:$D$11,2,'Establishment Water'!$B$28)*1.5,0),INDEX('Establishment Water'!$B$9:$D$11,2,'Establishment Water'!$B$28))&" days") | E18: =IF($A18="","",IF('Establishment Water'!$B39="Drought-adapted","No water",INDEX('Establishment Water'!$B$9:$D$11,3,'Establishment Water'!$B$28)&" days"))
A20: HOW TO WATER
A21: 1. | B21: Water slowly at the base of each plant: drip ring, soaker, watering bag, or a hose on a trickle. Do not use a sprinkler.
A22: 2. | B22: Water deeply and less often. Short, frequent watering keeps roots shallow.
A23: 3. | B23: Keep the mulch 3-4 in deep. Keep it pulled back from the trunk.
A24: 4. | B24: Heat wave (3 or more days above 100 F): give every plant one extra watering, early morning or evening, in any year.
A25: 5. | B25: 'No water' means no water. Those plants are harmed by summer water after the second year.
A26: 6. | B26: Stop all watering after the date above. Dry summers after year 3 make deep, strong roots.
A27: 7. | B27: Call your contact if leaves wilt, brown or drop outside of fall.

Sheet Conversion Economics
A1: CONVERSION ECONOMICS
A2: Blue cells are placeholder estimates. Replace them with local figures before relying on the results. The shape of the result holds; the paybacks will move.
A4: Labor rate ($/hour) | B4: ='Start Here'!$B$6 -> 150 | C4: From Start Here
A5: Planning horizon (years) | B5: ='Start Here'!$B$7 -> 15 | C5: From Start Here
A7: Scenario | B7: English Laurel | C7: Boxwood | D7: Photinia | E7: Bradford Pear | F7: Ash: keep treating vs. replace
A8: Unit basis | B8: 100 lf hedge | C8: 50 lf low hedge | D8: 100 lf hedge | E8: per tree | F8: per tree, DBH from Ash EAB
A9: CURRENT MAINTENANCE
A10: Service visits per year | B10: 2 | C10: 3 | D10: 4 | E10: 0.33 | F10: 0
A11: Labor hours per visit | B11: 5 | C11: 2 | D11: 3 | E11: 4 | F11: 0
A12: Other annual cost (injection, spray, replacements) | B12: 0 | C12: 0 | D12: 0 | E12: 0 | F12: ='Ash EAB'!$B$11*'Ash EAB'!$B$16/'Ash EAB'!$B$12 -> 108
A13: Annual cost | B13: =B10*B11*$B$4+B12 -> 1500 | C13: =C10*C11*$B$4+C12 -> 900 | D13: =D10*D11*$B$4+D12 -> 1800 | E13: =E10*E11*$B$4+E12 -> 198 | F13: =F10*F11*$B$4+F12 -> 108
A14: Cost over horizon | B14: =B13*$B$5 -> 22500 | C14: =C13*$B$5 -> 13500 | D14: =D13*$B$5 -> 27000 | E14: =E13*$B$5 -> 2970 | F14: =F13*$B$5 -> 1620
A15: ONE-TIME CONVERSION COST
A16: Removal labor hours | B16: 20 | C16: 6 | D16: 14 | E16: 8 | F16: 8
A17: Removal labor | B17: =B16*$B$4 -> 3000 | C17: =C16*$B$4 -> 900 | D17: =D16*$B$4 -> 2100 | E17: =E16*$B$4 -> 1200 | F17: =F16*$B$4 -> 1200
A18: Disposal / stump grinding | B18: 800 | C18: 200 | D18: 500 | E18: 400 | F18: 400
A19: Plant quantity | B19: 25 | C19: 17 | D19: 25 | E19: 1 | F19: 1
A20: Stock unit cost | B20: 55 | C20: 45 | D20: 55 | E20: 350 | F20: 350
A21: Install labor hours | B21: 10 | C21: 6 | D21: 10 | E21: 4 | F21: 4
A22: Establishment package, years 1-3 (mulch, checks, formative pruning) | B22: 900 | C22: 500 | D22: 900 | E22: 400 | F22: 400
A23: Hired watering, years 1-3 (0 if the owner waters; from Establishment Water) | B23: 0 | C23: 0 | D23: 0 | E23: 0 | F23: 0
A24: TOTAL CONVERSION COST | B24: =B17+B18+B19*B20+B21*$B$4+B22+B23 -> 7575 | C24: =C17+C18+C19*C20+C21*$B$4+C22+C23 -> 3265 | D24: =D17+D18+D19*D20+D21*$B$4+D22+D23 -> 6375 | E24: =E17+E18+E19*E20+E21*$B$4+E22+E23 -> 2950 | F24: =F17+F18+F19*F20+F21*$B$4+F22+F23 -> 2950
A25: CONVERTED MAINTENANCE
A26: Average visits per year over horizon | B26: 1 | C26: 1 | D26: 1 | E26: 0.33 | F26: 0.33
A27: Labor hours per visit | B27: 4 | C27: 2 | D27: 4 | E27: 2 | F27: 2
A28: Annual cost | B28: =B26*B27*$B$4 -> 600 | C28: =C26*C27*$B$4 -> 300 | D28: =D26*D27*$B$4 -> 600 | E28: =E26*E27*$B$4 -> 99 | F28: =F26*F27*$B$4 -> 99
A29: Cost over horizon | B29: =B28*$B$5 -> 9000 | C29: =C28*$B$5 -> 4500 | D29: =D28*$B$5 -> 9000 | E29: =E28*$B$5 -> 1485 | F29: =F28*$B$5 -> 1485
A30: RESULT
A31: Converted total (incl. conversion) | B31: =B24+B29 -> 16575 | C31: =C24+C29 -> 7765 | D31: =D24+D29 -> 15375 | E31: =E24+E29 -> 4435 | F31: =F24+F29 -> 4435
A32: Net difference vs. status quo (positive = saving) | B32: =B14-B31 -> 5925 | C32: =C14-C31 -> 5735 | D32: =D14-D31 -> 11625 | E32: =E14-E31 -> -1465 | F32: =F14-F31 -> -2815
A33: Annual savings after conversion | B33: =B13-B28 -> 900 | C33: =C13-C28 -> 600 | D33: =D13-D28 -> 1200 | E33: =E13-E28 -> 99 | F33: =F13-F28 -> 9
A34: Simple payback (years) | B34: =IF(B33<=0,"no payback",IF(B24/B33>50,"over 50 yrs",B24/B33)) -> 8.4166667 | C34: =IF(C33<=0,"no payback",IF(C24/C33>50,"over 50 yrs",C24/C33)) -> 5.4416667 | D34: =IF(D33<=0,"no payback",IF(D24/D33>50,"over 50 yrs",D24/D33)) -> 5.3125 | E34: =IF(E33<=0,"no payback",IF(E24/E33>50,"over 50 yrs",E24/E33)) -> 29.79798 | F34: =IF(F33<=0,"no payback",IF(F24/F33>50,"over 50 yrs",F24/F33)) -> over 50 yrs
A35: REMOVE SOON ONLY — COST OF WAITING
A36: Emergency removal cost if deferred | B36: 0 | C36: 0 | D36: 0 | E36: 2400 | F36: ='Ash EAB'!$B$16*'Ash EAB'!$B$13*'Ash EAB'!$B$14 -> 2160
